{
  "category": "Control",
  "name": "TRY_CATCH_FINALLY",
  "tests": [
    {
      "name": "try catch finally with exception",
      "script": [
        "TRY",
        "0x070A",
        "PUSH0",
        "THROW",
        "ENDT",
        "RET",
        "PUSH1",
        "ENDC",
        "RET",
        "PUSH2",
        "ENDF",
        "PUSH3"
      ],
      "steps": [
        {
          "actions": [
            "stepInto",
            "stepInto",
            "stepInto"
          ],
          "result": {
            "state": "BREAK",
            "invocationStack": [
              {
                "instructionPointer": 7,
                "nextInstruction": "PUSH1"
              }
            ]
          }
        },
        {
          "actions": [
            "stepInto",
            "stepInto"
          ],
          "result": {
            "state": "BREAK",
            "invocationStack": [
              {
                "instructionPointer": 10,
                "nextInstruction": "PUSH2",
                "evaluationStack": [
                  {
                    "type": "integer",
                    "value": 1
                  }
                ]
              }
            ]
          }
        },
        {
          "actions": [
            "stepInto",
            "stepInto"
          ],
          "result": {
            "state": "BREAK",
            "invocationStack": [
              {
                "instructionPointer": 12,
                "nextInstruction": "PUSH3",
                "evaluationStack": [
                  {
                    "type": "integer",
                    "value": 2
                  },
                  {
                    "type": "integer",
                    "value": 1
                  }
                ]
              }
            ]
          }
        }
      ]
    }
  ]
}
