{
  "category": "Control",
  "name": "TRY_CATCH_FINALLY",
  "tests": [
    {
      "name": "try{ try-catch } catch finally with exception",
      "script": [
        "TRY",
        "0x0b0e",
          "TRY",
          "0x0500",
            "THROW",
          "ENDT",
            "THROW",
          "ENDC",
        "ENDT",
          "PUSH2",
        "ENDC",
        "RET",
          "PUSH3",
        "ENDF",
          "PUSH4"
      ],
      "steps": [
        {
          "actions": [
            "stepInto",
            "stepInto",
            "stepInto"
          ],
          "result": {
            "state": "BREAK",
            "invocationStack": [
              {
                "instructionPointer": 8,
                "nextInstruction": "THROW"
              }
            ]
          }
        },
        {
          "actions": [
            "stepInto"
          ],
          "result": {
            "state": "BREAK",
            "invocationStack": [
              {
                "instructionPointer": 11,
                "nextInstruction": "PUSH2"
              }
            ]
          }
        },
        {
          "actions": [
            "stepInto",
            "stepInto",
            "stepInto",
            "stepInto"
          ],
          "result": {
            "state": "BREAK",
            "invocationStack": [
              {
                "instructionPointer": 13,
                "nextInstruction": "RET",
                "evaluationStack": [
                  {
                    "type": "integer",
                    "value": 3
                  },
                  {
                    "type": "integer",
                    "value": 2
                  }
                ]
              }
            ]
          }
        }
      ]
    }
  ]
}
